Workbook

Sheet Info
B7: Business planning | AG7: Modèle Zafy Tody
B10: Outil financier pour les startups
C21: Construire son business model et sa stratégie | O21: Gérer votre trésorerie et structurer votre plan de financement | AA21: Itérer et améliorer votre projet de startup | AM21: Exporter votre prévisionnel pour votre Business Plan
B27: Ceci est un outil conçu pour être simple et complet, dans le but d'aider l'entrepreneur dans la modélisation financière de son projet de création d'entreprise. Une connaissance minimale de la finance est néanmoins préférable pour tirer pleinement partie de l'outil. Conseil : Commencer par lire l'onglet "GUIDE" avant de démarrer l'utilisation.

Sheet Guide
B2: GUIDE
B5: Etape 0 : Introduction Un outil financier est un support d'aide à la réflexion de construction et de validation d'une stratégie d'entreprise. Pour utiliser cet outil, il faudra : 1 - Commencer par renseigner des informations sur le projet d'entreprise (ONGLETS CLAIRS) 2 - Analyser les résultats (ONGLETS FONCES) Une approche itérative de ces phases est généralement nécessaire pour affiner votre projet. Toute l'articulation de l'outil repose sur la possibilité de différencier plusieurs activités de revenus au sein de votre projet. Nous vous proposons de pouvoir gérer jusqu'à 12 "activités", même si la majorité des projets n'auront besoin de gérer qu'une ou deux activité(s). Les montants doivent être indiqués en Ar HT. Tous les calculs de TVA seront gérés automatiquement. La TVA est par défaut fixée à 20% mais peut être configurée dans l'onglet "CONFIG". Les feuilles sont "protégées" pour éviter que des erreurs de manipulations endommagent l'outil. Vous pouvez cependant dévérouiller ces feuilles sans mot de passe si vous souhaitez les personnaliser (clic droit sur l'onglet, puis "Ôter la protection des feuilles"). Certains onglets de calculs automatiques sont "masqués". Pour les visualiser, faites un clic droit sur la barre des onglets et choisissez "Afficher", puis sélectionnez l'onglet à afficher. Vous pouvez également si besoin créer des onglets personnalisés pour des calculs personnalisés.
B7: Etape 1 : Renseigner l'onglet "CONFIG" C'est le point de départ de la prise en main de l'outil. Commencez par renseigner les informations de "Configuration de base". Vous pourrez attaquer le renseignement des informations de "Configuration avancée" dans un second temps : ces informations sont pré-remplies pour vous simplifier la prise en main. Il vous sera très probablement nécéssaire de les ajuster à vos besoins par la suite.
B9: Etape 2 : Renseigner l'onglet "Personnel" Précisez les besoins en ressources humaines du projet au court du temps. Vous aurez à renseigner le salaire brut des personnes, mensuellement pour les années 1 et 2 et semestriellement pour les années 3 à 5. Les charges patronales sont calculées automatiquement. Vous pourrez modifier le taux de charges dans l'onglet "CONFIG". Pour les dirigeants au régime TNS, précisez directement un salaire totalement chargé.
B11: Etape 3 : Renseigner l'onglet "Charges externes" Précisez les charges externes de l'entreprise. Une partie est calculée automatiquement à partir d'informations, que vous pouvez modifier, définies dans la partie "Configuration avancée" de l'onglet "CONFIG". Vous pouvez également préciser d'autres charges mensuellement.
B13: Etape 4 : Renseigner l'onglet "Investissements" Précisez les investissements nécessaires pour le projet. Vous pouvez dissocier les types investissements par ligne. Pour chaque ligne, vous pourrez préciser les montants d'investisements mensuellement ainsi que les durées d'amortissement (tout à droite du tableau). Vous pouvez également préciser dans cet onglet les éventuels apports en nature que vous intégrez à l'entreprise.
B15: Etape 5 : Renseigner l'onglet "Commandes" Précisez les prévisions de commandes mensuelles par type d'activité. Le modèle propose un renseignement mensuel sur 5 ans pour vous faciliter la construction de prévisions estimatives à partir de fomules (fonction de votre business model et de vos hypothèses). Les encaissements et les décaissements liés à ces commandes (chiffres d'affaires et charges variables associées) seront calculés automatiquement sur la base des informations précisées dans l'onglet "CONFIG" (dans les tableaux "Chiffres d'Affaires" et "Charges variables").,
B17: Etape 6 : Renseigner l'onglet "Trésorerie" Préciser les financements identifiés pour le projet d'entreprise : capital (initial et augmentation par levée de fonds), prêts bancaires, subventions, … ainsi que certains besoins en financements à couvrir : stock moyen, remboursement de comptes courants et/ou d'avances, ...
B19: Etape 7 : Analyser les onglets "Synthèse", "Comptes de résultats", "Plan de financement" et "Bilans" Une fois les informations renseignées, l'outil générera les comptes de résultats de l'entreprise, les bilans, le plan de trésorerie menusel, le plan de financement, les points morts par années d'activités, le BFR ... et des graphiques que vous retrouverez dans l'onglet de synthèse. Ces informations vous permettront d'analyser le potentiel du projet, les enjeux commerciaux, les enjeux de financements, ... Vous pouvez désormais travailler par itération pour affiner votre vision financière de votre projet et votre stratégie d'entreprise.

Sheet Config
B2: CONFIGURATION DE BASE
B5: Note : Informations à renseigner pour démarrer votre prévisionnel. L'onglet "CONFIG" possède plus bas une deuxième zone de "Configuration avancée" à ne remplir qu'une fois que l'outil vous est plus familier.
B7: Date de démarrage de l'activité | C7: 45505
B9: CHIFFRE D'AFFAIRES
B11: Note sur la construction du chiffre d'affaires : Vous pouvez gérer plusieurs activités de revenus dans ce prévisionnel financier. Commencez par indiquer les intitulés de vos activités. Renseignez par activité de revenus : - Le revenu unitaire (par unité commandée. Le nombre d'unités commandées étant défini mensuellement dans l'onglet "Commandes") - Le délai de livraison (temps de production+livraison) - Le délai de paiement client - L'acompte éventuellement payé par le client à la commande - Le solde final payé à date de livraison + délai de paiement (automatique)
B13: Dénomination de l'activité | C13: Prix unitaire (en HT) | D13: Délai de livraison (en mois) | E13: Délai de paiement (en mois) | F13: Acompte initial (en %) | G13: Solde (en %)
B14: Abonnement Basique | C14: 15000 | D14: 0 | E14: 0 | F14: 0 | G14: =1-F14 -> 1
B15: Abonnement Premium | C15: 25000 | D15: 0 | E15: 0 | F15: 0 | G15: =1-F15 -> 1
B16: Conseil Personnalisé | C16: 12000 | D16: 0 | E16: 0 | F16: 0 | G16: =1-F16 -> 1
B17: Plateforme de Marché en Ligne | C17: 8000 | D17: 0 | E17: 0 | F17: 0 | G17: =1-F17 -> 1
B18: Formations et Ateliers | C18: 10000 | D18: 0 | E18: 0 | F18: 0 | G18: =1-F18 -> 1
B19: Commission ventes 2% | C19: 3000 | D19: 0 | E19: 0 | F19: 0 | G19: =1-F19 -> 1
G20: =1-F20 -> 1
G21: =1-F21 -> 1
G22: =1-F22 -> 1
G23: =1-F23 -> 1
G24: =1-F24 -> 1
G25: =1-F25 -> 1
B27: CHARGES VARIABLES
B29: Note sur les charges variables : Ces informations permettent de calculer automatiquement les charges variables associées aux commandes précisées dans l'onglet "Commandes". Les données à renseigner suivent le même modèle que le tableau ci-dessus. Les charges variables pour une activité donnée correspondent aux achats de matières premières et de sous-traitances que votre entreprises devra faire pour réaliser et livrer une unité commandée. Les informations sont donc liées à vos conditions commerciales négociées avec vos fournisseurs et prestataires : prix, délai de livraison, délai de paiement, acompte initial et solde du paiement.
B31: Dénomination de l'activité | C31: Coût unitaire (en HT) | D31: Délai de livraison (en mois) | E31: Délai de paiement (en mois) | F31: Acompte initial (en %) | G31: Solde (en %)
B32: =B14 -> Abonnement Basique | C32: 15000 | D32: 0 | G32: =1-F32 -> 1
B33: =B15 -> Abonnement Premium | C33: 25000 | D33: 0 | G33: =1-F33 -> 1
B34: =B16 -> Conseil Personnalisé | C34: 12000 | D34: 0 | G34: =1-F34 -> 1
B35: =B17 -> Plateforme de Marché en Ligne | C35: 8000 | D35: 0 | G35: =1-F35 -> 1
B36: =B18 -> Formations et Ateliers | C36: 10000 | D36: 0 | G36: =1-F36 -> 1
B37: =B19 -> Commission ventes 2% | C37: 3000 | D37: 0 | G37: =1-F37 -> 1
B38: =B20 | G38: =1-F38 -> 1
B39: =B21 | G39: =1-F39 -> 1
B40: =B22 | G40: =1-F40 -> 1
B41: =B23 | G41: =1-F41 -> 1
B42: =B24 | G42: =1-F42 -> 1
B43: =B25 | G43: =1-F43 -> 1
B45: CONFIGURATION AVANCEE
B48: Note : Une fois que vous avez pris en main l'outil, vous pouvez affiner vos prévisions en personnalisant les données par défaut de cette partie "Configuration avancée".
B50: CHARGES EXTERNES ANNUELLES
B52: Note : Ce tableau permet de calculer automatiquement les charges externes de l'entreprise. Pour mieux comprendre comment est calculée chaque ligne, veuillez vous référer aux commentaires associés. Des valeurs par défaut sont proposées à titre indicatif pour simplifier la prise en main initiale de l'outil et seront à affiner en fonction du projet. Vous pouvez aussi définir des charges externes sur mesure dans l'onglet "Charges externes".
B54: Poste | C54: Fixe ( HT) | D54: Variable | E54: Commentaires
B55: Frais de déplacement | C55: 450000 | D55: 0.01 | E55: Calculé sur la base d'un forfait fixe annuel + variable en % du CA
B56: Honoraires | C56: 4800000 | D56: 0 | E56: Calculé sur la base d'un forfait fixe annuel + variable par salarié
...

Sheet Personnel
B2: PERSONNEL
B5: Note : Renseignez dans cet onglet les informations sur le personnel de l'entreprise : Type de poste, salaires bruts annuels et nombre de salariés (par mois pour les années 1 et 2, puis par semestre). Pour les régimes TNS, précisez les salaires totalement chargés.
B7: Poste | C7: Année 1 | Q7: Année 2 | AE7: Année 3 | AI7: Année 4 | AM7: Année 5
C8: Salaires bruts annuels | D8: Nombre de salariés | Q8: Salaires bruts annuels | R8: Nombre de salariés | AE8: Salaires bruts annuels | AF8: Nombre de salariés | AI8: Salaires bruts annuels | AJ8: Nombre de salariés | AM8: Salaires bruts annuels | AN8: Nombre de salariés
D9: =Config!$C$7 -> 45505 | E9: =DATE(YEAR(D9),MONTH(D9)+1,DAY(D9)) -> 45536 | F9: =DATE(YEAR(E9),MONTH(E9)+1,DAY(E9)) -> 45566 | G9: =DATE(YEAR(F9),MONTH(F9)+1,DAY(F9)) -> 45597 | H9: =DATE(YEAR(G9),MONTH(G9)+1,DAY(G9)) -> 45627 | I9: =DATE(YEAR(H9),MONTH(H9)+1,DAY(H9)) -> 45658 | J9: =DATE(YEAR(I9),MONTH(I9)+1,DAY(I9)) -> 45689 | K9: =DATE(YEAR(J9),MONTH(J9)+1,DAY(J9)) -> 45717 | L9: =DATE(YEAR(K9),MONTH(K9)+1,DAY(K9)) -> 45748 | ... O9: =DATE(YEAR(N9),MONTH(N9)+1,DAY(N9)) -> 45839 | P9: ETP | R9: =DATE(YEAR(O9),MONTH(O9)+1,DAY(O9)) -> 45870 | S9: =DATE(YEAR(R9),MONTH(R9)+1,DAY(R9)) -> 45901 | T9: =DATE(YEAR(S9),MONTH(S9)+1,DAY(S9)) -> 45931 | U9: =DATE(YEAR(T9),MONTH(T9)+1,DAY(T9)) -> 45962 | V9: =DATE(YEAR(U9),MONTH(U9)+1,DAY(U9)) -> 45992 | W9: =DATE(YEAR(V9),MONTH(V9)+1,DAY(V9)) -> 46023 | X9: =DATE(YEAR(W9),MONTH(W9)+1,DAY(W9)) -> 46054 | Y9: =DATE(YEAR(X9),MONTH(X9)+1,DAY(X9)) -> 46082 | Z9: =DATE(YEAR(Y9),MONTH(Y9)+1,DAY(Y9)) -> 46113 | ... AC9: =DATE(YEAR(AB9),MONTH(AB9)+1,DAY(AB9)) -> 46204 | AD9: ETP | AF9: S1 | AG9: S2 | AH9: ETP | AJ9: S1 | AK9: S2 | AL9: ETP | AN9: S1 | AO9: S2 | AP9: ETP
B10: Dirigeant (régime TNS) | C10: 34000 | P10: =SUM(D10:O10)/12 -> 0 | AD10: =SUM(R10:AC10)/12 -> 0 | AH10: =SUM(AF10:AG10)/2 -> 0 | AL10: =SUM(AJ10:AK10)/2 -> 0 | AP10: =SUM(AN10:AO10)/2 -> 0
B11: Dirigeant (régime TNS) | P11: =SUM(D11:O11)/12 -> 0 | AD11: =SUM(R11:AC11)/12 -> 0 | AH11: =SUM(AF11:AG11)/2 -> 0 | AL11: =SUM(AJ11:AK11)/2 -> 0 | AP11: =SUM(AN11:AO11)/2 -> 0
B12: Dirigeant (salarié) | C12: 15600000 | D12: 1 | E12: 1 | F12: 1 | G12: 1 | H12: 1 | I12: 1 | J12: 1 | K12: 1 | L12: 1 | M12: 1 | N12: 1 | O12: 1 | P12: =SUM(D12:O12)/12 -> 1 | Q12: 31400000 | R12: 1 | S12: 1 | T12: 1 | U12: 1 | V12: 1 | W12: 1 | X12: 1 | Y12: 1 | Z12: 1 | AA12: 1 | AB12: 1 | AC12: 1 | AD12: =SUM(R12:AC12)/12 -> 1 | AE12: 47700000 | AF12: 1 | AG12: 1 | AH12: =SUM(AF12:AG12)/2 -> 1 | AL12: =SUM(AJ12:AK12)/2 -> 0 | AP12: =SUM(AN12:AO12)/2 -> 0
B13: Dirigeant (salarié) | C13: 15600000 | D13: 1 | E13: 1 | F13: 1 | G13: 1 | H13: 1 | I13: 1 | J13: 1 | K13: 1 | L13: 1 | M13: 1 | N13: 1 | O13: 1 | P13: =SUM(D13:O13)/12 -> 1 | Q13: 31400000 | R13: 1 | S13: 1 | T13: 1 | U13: 1 | V13: 1 | W13: 1 | X13: 1 | Y13: 1 | Z13: 1 | AA13: 1 | AB13: 1 | AC13: 1 | AD13: =SUM(R13:AC13)/12 -> 1 | AE13: 47700000 | AF13: 1 | AG13: 1 | AH13: =SUM(AF13:AG13)/2 -> 1 | AL13: =SUM(AJ13:AK13)/2 -> 0 | AP13: =SUM(AN13:AO13)/2 -> 0
B14: Réceptionniste | C14: 7800000 | I14: 1 | J14: 1 | K14: 1 | L14: 1 | M14: 1 | N14: 1 | O14: 1 | P14: =SUM(D14:O14)/12 -> 0.58333333 | Q14: 9600000 | R14: 1 | S14: 1 | T14: 1 | U14: 1 | V14: 1 | W14: 2 | X14: 2 | Y14: 2 | Z14: 2 | AA14: 2 | AB14: 2 | AC14: 2 | AD14: =SUM(R14:AC14)/12 -> 1.5833333 | AE14: 15600000 | AF14: 2 | AG14: 3 | AH14: =SUM(AF14:AG14)/2 -> 2.5 | AL14: =SUM(AJ14:AK14)/2 -> 0 | AP14: =SUM(AN14:AO14)/2 -> 0
B15: Couturière | C15: 9600000 | I15: 1 | J15: 1 | K15: 1 | L15: 1 | M15: 1 | N15: 1 | O15: 1 | P15: =SUM(D15:O15)/12 -> 0.58333333 | Q15: 15600000 | R15: 1 | S15: 1 | T15: 1 | U15: 1 | V15: 1 | W15: 1 | X15: 1 | Y15: 1 | Z15: 1 | AA15: 1 | AB15: 1 | AC15: 1 | AD15: =SUM(R15:AC15)/12 -> 1 | AE15: 21400000 | AF15: 2 | AG15: 2 | AH15: =SUM(AF15:AG15)/2 -> 2 | AL15: =SUM(AJ15:AK15)/2 -> 0 | AP15: =SUM(AN15:AO15)/2 -> 0
P16: =SUM(D16:O16)/12 -> 0 | AD16: =SUM(R16:AC16)/12 -> 0 | AH16: =SUM(AF16:AG16)/2 -> 0 | AL16: =SUM(AJ16:AK16)/2 -> 0 | AP16: =SUM(AN16:AO16)/2 -> 0
P17: =SUM(D17:O17)/12 -> 0 | AD17: =SUM(R17:AC17)/12 -> 0 | AH17: =SUM(AF17:AG17)/2 -> 0 | AL17: =SUM(AJ17:AK17)/2 -> 0 | AP17: =SUM(AN17:AO17)/2 -> 0
P18: =SUM(D18:O18)/12 -> 0 | AD18: =SUM(R18:AC18)/12 -> 0 | AH18: =SUM(AF18:AG18)/2 -> 0 | AL18: =SUM(AJ18:AK18)/2 -> 0 | AP18: =SUM(AN18:AO18)/2 -> 0
P19: =SUM(D19:O19)/12 -> 0 | AD19: =SUM(R19:AC19)/12 -> 0 | AH19: =SUM(AF19:AG19)/2 -> 0 | AL19: =SUM(AJ19:AK19)/2 -> 0 | AP19: =SUM(AN19:AO19)/2 -> 0
P20: =SUM(D20:O20)/12 -> 0 | AD20: =SUM(R20:AC20)/12 -> 0 | AH20: =SUM(AF20:AG20)/2 -> 0 | AL20: =SUM(AJ20:AK20)/2 -> 0 | AP20: =SUM(AN20:AO20)/2 -> 0
P21: =SUM(D21:O21)/12 -> 0 | AD21: =SUM(R21:AC21)/12 -> 0 | AH21: =SUM(AF21:AG21)/2 -> 0 | AL21: =SUM(AJ21:AK21)/2 -> 0 | AP21: =SUM(AN21:AO21)/2 -> 0
P22: =SUM(D22:O22)/12 -> 0 | AD22: =SUM(R22:AC22)/12 -> 0 | AH22: =SUM(AF22:AG22)/2 -> 0 | AL22: =SUM(AJ22:AK22)/2 -> 0 | AP22: =SUM(AN22:AO22)/2 -> 0
P23: =SUM(D23:O23)/12 -> 0 | AD23: =SUM(R23:AC23)/12 -> 0 | AH23: =SUM(AF23:AG23)/2 -> 0 | AL23: =SUM(AJ23:AK23)/2 -> 0 | AP23: =SUM(AN23:AO23)/2 -> 0
P24: =SUM(D24:O24)/12 -> 0 | AD24: =SUM(R24:AC24)/12 -> 0 | AH24: =SUM(AF24:AG24)/2 -> 0 | AL24: =SUM(AJ24:AK24)/2 -> 0 | AP24: =SUM(AN24:AO24)/2 -> 0
P25: =SUM(D25:O25)/12 -> 0 | AD25: =SUM(R25:AC25)/12 -> 0 | AH25: =SUM(AF25:AG25)/2 -> 0 | AL25: =SUM(AJ25:AK25)/2 -> 0 | AP25: =SUM(AN25:AO25)/2 -> 0
P26: =SUM(D26:O26)/12 -> 0 | AD26: =SUM(R26:AC26)/12 -> 0 | AH26: =SUM(AF26:AG26)/2 -> 0 | AL26: =SUM(AJ26:AK26)/2 -> 0 | AP26: =SUM(AN26:AO26)/2 -> 0
P27: =SUM(D27:O27)/12 -> 0 | AD27: =SUM(R27:AC27)/12 -> 0 | AH27: =SUM(AF27:AG27)/2 -> 0 | AL27: =SUM(AJ27:AK27)/2 -> 0 | AP27: =SUM(AN27:AO27)/2 -> 0
... P29: =SUM(D29:O29)/12 -> 0 | AD29: =SUM(R29:AC29)/12 -> 0 | AH29: =SUM(AF29:AG29)/2 -> 0 | AL29: =SUM(AJ29:AK29)/2 -> 0 | AP29: =SUM(AN29:AO29)/2 -> 0
B30: TOTAL | D30: =SUM(D10:D29) -> 2 | E30: =SUM(E10:E29) -> 2 | F30: =SUM(F10:F29) -> 2 | G30: =SUM(G10:G29) -> 2 | H30: =SUM(H10:H29) -> 2 | I30: =SUM(I10:I29) -> 4 | J30: =SUM(J10:J29) -> 4 | K30: =SUM(K10:K29) -> 4 | ... P30: =SUM(P10:P29) -> 3.1666667 | R30: =SUM(R10:R29) -> 4 | S30: =SUM(S10:S29) -> 4 | T30: =SUM(T10:T29) -> 4 | U30: =SUM(U10:U29) -> 4 | V30: =SUM(V10:V29) -> 4 | W30: =SUM(W10:W29) -> 5 | X30: =SUM(X10:X29) -> 5 | Y30: =SUM(Y10:Y29) -> 5 | ... AD30: =SUM(AD10:AD29) -> 4.5833333 | AF30: =SUM(AF10:AF29) -> 6 | AG30: =SUM(AG10:AG29) -> 7 | AH30: =SUM(AH10:AH29) -> 6.5 | AJ30: =SUM(AJ10:AJ29) -> 0 | AK30: =SUM(AK10:AK29) -> 0 | AL30: =SUM(AL10:AL29) -> 0 | AN30: =SUM(AN10:AN29) -> 0 | AO30: =SUM(AO10:AO29) -> 0 | AP30: =SUM(AP10:AP29) -> 0

Sheet Charges variables
B2: Charges variables (en € HT)
B5: Note : Ces tableaux sont remplis automatiquement après avoir complété les informations dans l'onglet "Configuration" liées aux "Charges variables" et les informations des commandes prévisionnelles dans l'onglet "Commandes".
C7: Année 1 | O7: Année 2 | AA7: Année 3 | AM7: Année 4 | AY7: Année 5
B8: Charges totales décaissées | C8: =Config!$C$7 -> 45505 | D8: =DATE(YEAR(C8),MONTH(C8)+1,DAY(C8)) -> 45536 | E8: =DATE(YEAR(D8),MONTH(D8)+1,DAY(D8)) -> 45566 | F8: =DATE(YEAR(E8),MONTH(E8)+1,DAY(E8)) -> 45597 | G8: =DATE(YEAR(F8),MONTH(F8)+1,DAY(F8)) -> 45627 | H8: =DATE(YEAR(G8),MONTH(G8)+1,DAY(G8)) -> 45658 | I8: =DATE(YEAR(H8),MONTH(H8)+1,DAY(H8)) -> 45689 | J8: =DATE(YEAR(I8),MONTH(I8)+1,DAY(I8)) -> 45717 | K8: =DATE(YEAR(J8),MONTH(J8)+1,DAY(J8)) -> 45748 | ... BJ8: =DATE(YEAR(BI8),MONTH(BI8)+1,DAY(BI8)) -> 47300
B9: =Config!$B$14 -> Abonnement Basique | C9: {=((Config!$F32*Commandes!C9)+IF(ROUND((C$8-Config!$C$7)/31,0)>=(Config!$D32+Config!$E32),INDEX(Commandes!$C9:Commandes!$BJ9,,COLUMN(C$8)-COLUMN($C$8)+1-(Config!$D32+Config!$E32)),0)*(1-Config!$F32))*Config!$C32} -> 0 | D9: {=((Config!$F32*Commandes!D9)+IF(ROUND((D$8-Config!$C$7)/31,0)>=(Config!$D32+Config!$E32),INDEX(Commandes!$C9:Commandes!$BJ9,,COLUMN(D$8)-COLUMN($C$8)+1-(Config!$D32+Config!$E32)),0)*(1-Config!$F32))*Config!$C32} -> 0 | E9: {=((Config!$F32*Commandes!E9)+IF(ROUND((E$8-Config!$C$7)/31,0)>=(Config!$D32+Config!$E32),INDEX(Commandes!$C9:Commandes!$BJ9,,COLUMN(E$8)-COLUMN($C$8)+1-(Config!$D32+Config!$E32)),0)*(1-Config!$F32))*Config!$C32} -> 450000 | F9: {=((Config!$F32*Commandes!F9)+IF(ROUND((F$8-Config!$C$7)/31,0)>=(Config!$D32+Config!$E32),INDEX(Commandes!$C9:Commandes!$BJ9,,COLUMN(F$8)-COLUMN($C$8)+1-(Config!$D32+Config!$E32)),0)*(1-Config!$F32))*Config!$C32} -> 750000 | G9: {=((Config!$F32*Commandes!G9)+IF(ROUND((G$8-Config!$C$7)/31,0)>=(Config!$D32+Config!$E32),INDEX(Commandes!$C9:Commandes!$BJ9,,COLUMN(G$8)-COLUMN($C$8)+1-(Config!$D32+Config!$E32)),0)*(1-Config!$F32))*Config!$C32} -> 1125000 | H9: {=((Config!$F32*Commandes!H9)+IF(ROUND((H$8-Config!$C$7)/31,0)>=(Config!$D32+Config!$E32),INDEX(Commandes!$C9:Commandes!$BJ9,,COLUMN(H$8)-COLUMN($C$8)+1-(Config!$D32+Config!$E32)),0)*(1-Config!$F32))*Config!$C32} -> 1500000 | I9: {=((Config!$F32*Commandes!I9)+IF(ROUND((I$8-Config!$C$7)/31,0)>=(Config!$D32+Config!$E32),INDEX(Commandes!$C9:Commandes!$BJ9,,COLUMN(I$8)-COLUMN($C$8)+1-(Config!$D32+Config!$E32)),0)*(1-Config!$F32))*Config!$C32} -> 1650000 | J9: {=((Config!$F32*Commandes!J9)+IF(ROUND((J$8-Config!$C$7)/31,0)>=(Config!$D32+Config!$E32),INDEX(Commandes!$C9:Commandes!$BJ9,,COLUMN(J$8)-COLUMN($C$8)+1-(Config!$D32+Config!$E32)),0)*(1-Config!$F32))*Config!$C32} -> 1815000 | ... BJ9: {=((Config!$F32*Commandes!BJ9)+IF(ROUND((BJ$8-Config!$C$7)/31,0)>=(Config!$D32+Config!$E32),INDEX(Commandes!$C9:Commandes!$BJ9,,COLUMN(BJ$8)-COLUMN($C$8)+1-(Config!$D32+Config!$E32)),0)*(1-Config!$F32))*Config!$C32} -> 450000000
B10: =Config!$B$15 -> Abonnement Premium | C10: {=((Config!$F33*Commandes!C10)+IF(ROUND((C$8-Config!$C$7)/31,0)>=(Config!$D33+Config!$E33),INDEX(Commandes!$C10:Commandes!$BJ10,,COLUMN(C$8)-COLUMN($C$8)+1-(Config!$D33+Config!$E33)),0)*(1-Config!$F33))*Config!$C33} -> 0 | D10: {=((Config!$F33*Commandes!D10)+IF(ROUND((D$8-Config!$C$7)/31,0)>=(Config!$D33+Config!$E33),INDEX(Commandes!$C10:Commandes!$BJ10,,COLUMN(D$8)-COLUMN($C$8)+1-(Config!$D33+Config!$E33)),0)*(1-Config!$F33))*Config!$C33} -> 0 | E10: {=((Config!$F33*Commandes!E10)+IF(ROUND((E$8-Config!$C$7)/31,0)>=(Config!$D33+Config!$E33),INDEX(Commandes!$C10:Commandes!$BJ10,,COLUMN(E$8)-COLUMN($C$8)+1-(Config!$D33+Config!$E33)),0)*(1-Config!$F33))*Config!$C33} -> 1250000 | F10: {=((Config!$F33*Commandes!F10)+IF(ROUND((F$8-Config!$C$7)/31,0)>=(Config!$D33+Config!$E33),INDEX(Commandes!$C10:Commandes!$BJ10,,COLUMN(F$8)-COLUMN($C$8)+1-(Config!$D33+Config!$E33)),0)*(1-Config!$F33))*Config!$C33} -> 2500000 | G10: {=((Config!$F33*Commandes!G10)+IF(ROUND((G$8-Config!$C$7)/31,0)>=(Config!$D33+Config!$E33),INDEX(Commandes!$C10:Commandes!$BJ10,,COLUMN(G$8)-COLUMN($C$8)+1-(Config!$D33+Config!$E33)),0)*(1-Config!$F33))*Config!$C33} -> 5000000 | H10: {=((Config!$F33*Commandes!H10)+IF(ROUND((H$8-Config!$C$7)/31,0)>=(Config!$D33+Config!$E33),INDEX(Commandes!$C10:Commandes!$BJ10,,COLUMN(H$8)-COLUMN($C$8)+1-(Config!$D33+Config!$E33)),0)*(1-Config!$F33))*Config!$C33} -> 12500000 | I10: {=((Config!$F33*Commandes!I10)+IF(ROUND((I$8-Config!$C$7)/31,0)>=(Config!$D33+Config!$E33),INDEX(Commandes!$C10:Commandes!$BJ10,,COLUMN(I$8)-COLUMN($C$8)+1-(Config!$D33+Config!$E33)),0)*(1-Config!$F33))*Config!$C33} -> 20000000 | J10: {=((Config!$F33*Commandes!J10)+IF(ROUND((J$8-Config!$C$7)/31,0)>=(Config!$D33+Config!$E33),INDEX(Commandes!$C10:Commandes!$BJ10,,COLUMN(J$8)-COLUMN($C$8)+1-(Config!$D33+Config!$E33)),0)*(1-Config!$F33))*Config!$C33} -> 25000000 | ... BJ10: {=((Config!$F33*Commandes!BJ10)+IF(ROUND((BJ$8-Config!$C$7)/31,0)>=(Config!$D33+Config!$E33),INDEX(Commandes!$C10:Commandes!$BJ10,,COLUMN(BJ$8)-COLUMN($C$8)+1-(Config!$D33+Config!$E33)),0)*(1-Config!$F33))*Config!$C33} -> 500000000
B11: =Config!$B$16 -> Conseil Personnalisé | C11: {=((Config!$F34*Commandes!C11)+IF(ROUND((C$8-Config!$C$7)/31,0)>=(Config!$D34+Config!$E34),INDEX(Commandes!$C11:Commandes!$BJ11,,COLUMN(C$8)-COLUMN($C$8)+1-(Config!$D34+Config!$E34)),0)*(1-Config!$F34))*Config!$C34} -> 0 | D11: {=((Config!$F34*Commandes!D11)+IF(ROUND((D$8-Config!$C$7)/31,0)>=(Config!$D34+Config!$E34),INDEX(Commandes!$C11:Commandes!$BJ11,,COLUMN(D$8)-COLUMN($C$8)+1-(Config!$D34+Config!$E34)),0)*(1-Config!$F34))*Config!$C34} -> 0 | E11: {=((Config!$F34*Commandes!E11)+IF(ROUND((E$8-Config!$C$7)/31,0)>=(Config!$D34+Config!$E34),INDEX(Commandes!$C11:Commandes!$BJ11,,COLUMN(E$8)-COLUMN($C$8)+1-(Config!$D34+Config!$E34)),0)*(1-Config!$F34))*Config!$C34} -> 0 | F11: {=((Config!$F34*Commandes!F11)+IF(ROUND((F$8-Config!$C$7)/31,0)>=(Config!$D34+Config!$E34),INDEX(Commandes!$C11:Commandes!$BJ11,,COLUMN(F$8)-COLUMN($C$8)+1-(Config!$D34+Config!$E34)),0)*(1-Config!$F34))*Config!$C34} -> 0 | G11: {=((Config!$F34*Commandes!G11)+IF(ROUND((G$8-Config!$C$7)/31,0)>=(Config!$D34+Config!$E34),INDEX(Commandes!$C11:Commandes!$BJ11,,COLUMN(G$8)-COLUMN($C$8)+1-(Config!$D34+Config!$E34)),0)*(1-Config!$F34))*Config!$C34} -> 0 | H11: {=((Config!$F34*Commandes!H11)+IF(ROUND((H$8-Config!$C$7)/31,0)>=(Config!$D34+Config!$E34),INDEX(Commandes!$C11:Commandes!$BJ11,,COLUMN(H$8)-COLUMN($C$8)+1-(Config!$D34+Config!$E34)),0)*(1-Config!$F34))*Config!$C34} -> 7200000 | I11: {=((Config!$F34*Commandes!I11)+IF(ROUND((I$8-Config!$C$7)/31,0)>=(Config!$D34+Config!$E34),INDEX(Commandes!$C11:Commandes!$BJ11,,COLUMN(I$8)-COLUMN($C$8)+1-(Config!$D34+Config!$E34)),0)*(1-Config!$F34))*Config!$C34} -> 7200000 | J11: {=((Config!$F34*Commandes!J11)+IF(ROUND((J$8-Config!$C$7)/31,0)>=(Config!$D34+Config!$E34),INDEX(Commandes!$C11:Commandes!$BJ11,,COLUMN(J$8)-COLUMN($C$8)+1-(Config!$D34+Config!$E34)),0)*(1-Config!$F34))*Config!$C34} -> 7200000 | ... BJ11: {=((Config!$F34*Commandes!BJ11)+IF(ROUND((BJ$8-Config!$C$7)/31,0)>=(Config!$D34+Config!$E34),INDEX(Commandes!$C11:Commandes!$BJ11,,COLUMN(BJ$8)-COLUMN($C$8)+1-(Config!$D34+Config!$E34)),0)*(1-Config!$F34))*Config!$C34} -> 18000000
B12: =Config!$B$17 -> Plateforme de Marché en Ligne | C12: {=((Config!$F35*Commandes!C12)+IF(ROUND((C$8-Config!$C$7)/31,0)>=(Config!$D35+Config!$E35),INDEX(Commandes!$C12:Commandes!$BJ12,,COLUMN(C$8)-COLUMN($C$8)+1-(Config!$D35+Config!$E35)),0)*(1-Config!$F35))*Config!$C35} -> 0 | D12: {=((Config!$F35*Commandes!D12)+IF(ROUND((D$8-Config!$C$7)/31,0)>=(Config!$D35+Config!$E35),INDEX(Commandes!$C12:Commandes!$BJ12,,COLUMN(D$8)-COLUMN($C$8)+1-(Config!$D35+Config!$E35)),0)*(1-Config!$F35))*Config!$C35} -> 0 | E12: {=((Config!$F35*Commandes!E12)+IF(ROUND((E$8-Config!$C$7)/31,0)>=(Config!$D35+Config!$E35),INDEX(Commandes!$C12:Commandes!$BJ12,,COLUMN(E$8)-COLUMN($C$8)+1-(Config!$D35+Config!$E35)),0)*(1-Config!$F35))*Config!$C35} -> 0 | F12: {=((Config!$F35*Commandes!F12)+IF(ROUND((F$8-Config!$C$7)/31,0)>=(Config!$D35+Config!$E35),INDEX(Commandes!$C12:Commandes!$BJ12,,COLUMN(F$8)-COLUMN($C$8)+1-(Config!$D35+Config!$E35)),0)*(1-Config!$F35))*Config!$C35} -> 0 | G12: {=((Config!$F35*Commandes!G12)+IF(ROUND((G$8-Config!$C$7)/31,0)>=(Config!$D35+Config!$E35),INDEX(Commandes!$C12:Commandes!$BJ12,,COLUMN(G$8)-COLUMN($C$8)+1-(Config!$D35+Config!$E35)),0)*(1-Config!$F35))*Config!$C35} -> 0 | H12: {=((Config!$F35*Commandes!H12)+IF(ROUND((H$8-Config!$C$7)/31,0)>=(Config!$D35+Config!$E35),INDEX(Commandes!$C12:Commandes!$BJ12,,COLUMN(H$8)-COLUMN($C$8)+1-(Config!$D35+Config!$E35)),0)*(1-Config!$F35))*Config!$C35} -> 0 | I12: {=((Config!$F35*Commandes!I12)+IF(ROUND((I$8-Config!$C$7)/31,0)>=(Config!$D35+Config!$E35),INDEX(Commandes!$C12:Commandes!$BJ12,,COLUMN(I$8)-COLUMN($C$8)+1-(Config!$D35+Config!$E35)),0)*(1-Config!$F35))*Config!$C35} -> 0 | J12: {=((Config!$F35*Commandes!J12)+IF(ROUND((J$8-Config!$C$7)/31,0)>=(Config!$D35+Config!$E35),INDEX(Commandes!$C12:Commandes!$BJ12,,COLUMN(J$8)-COLUMN($C$8)+1-(Config!$D35+Config!$E35)),0)*(1-Config!$F35))*Config!$C35} -> 0 | ... BJ12: {=((Config!$F35*Commandes!BJ12)+IF(ROUND((BJ$8-Config!$C$7)/31,0)>=(Config!$D35+Config!$E35),INDEX(Commandes!$C12:Commandes!$BJ12,,COLUMN(BJ$8)-COLUMN($C$8)+1-(Config!$D35+Config!$E35)),0)*(1-Config!$F35))*Config!$C35} -> 0
B13: =Config!$B$18 -> Formations et Ateliers | C13: {=((Config!$F36*Commandes!C13)+IF(ROUND((C$8-Config!$C$7)/31,0)>=(Config!$D36+Config!$E36),INDEX(Commandes!$C13:Commandes!$BJ13,,COLUMN(C$8)-COLUMN($C$8)+1-(Config!$D36+Config!$E36)),0)*(1-Config!$F36))*Config!$C36} -> 0 | D13: {=((Config!$F36*Commandes!D13)+IF(ROUND((D$8-Config!$C$7)/31,0)>=(Config!$D36+Config!$E36),INDEX(Commandes!$C13:Commandes!$BJ13,,COLUMN(D$8)-COLUMN($C$8)+1-(Config!$D36+Config!$E36)),0)*(1-Config!$F36))*Config!$C36} -> 0 | E13: {=((Config!$F36*Commandes!E13)+IF(ROUND((E$8-Config!$C$7)/31,0)>=(Config!$D36+Config!$E36),INDEX(Commandes!$C13:Commandes!$BJ13,,COLUMN(E$8)-COLUMN($C$8)+1-(Config!$D36+Config!$E36)),0)*(1-Config!$F36))*Config!$C36} -> 0 | F13: {=((Config!$F36*Commandes!F13)+IF(ROUND((F$8-Config!$C$7)/31,0)>=(Config!$D36+Config!$E36),INDEX(Commandes!$C13:Commandes!$BJ13,,COLUMN(F$8)-COLUMN($C$8)+1-(Config!$D36+Config!$E36)),0)*(1-Config!$F36))*Config!$C36} -> 0 | G13: {=((Config!$F36*Commandes!G13)+IF(ROUND((G$8-Config!$C$7)/31,0)>=(Config!$D36+Config!$E36),INDEX(Commandes!$C13:Commandes!$BJ13,,COLUMN(G$8)-COLUMN($C$8)+1-(Config!$D36+Config!$E36)),0)*(1-Config!$F36))*Config!$C36} -> 0 | H13: {=((Config!$F36*Commandes!H13)+IF(ROUND((H$8-Config!$C$7)/31,0)>=(Config!$D36+Config!$E36),INDEX(Commandes!$C13:Commandes!$BJ13,,COLUMN(H$8)-COLUMN($C$8)+1-(Config!$D36+Config!$E36)),0)*(1-Config!$F36))*Config!$C36} -> 0 | I13: {=((Config!$F36*Commandes!I13)+IF(ROUND((I$8-Config!$C$7)/31,0)>=(Config!$D36+Config!$E36),INDEX(Commandes!$C13:Commandes!$BJ13,,COLUMN(I$8)-COLUMN($C$8)+1-(Config!$D36+Config!$E36)),0)*(1-Config!$F36))*Config!$C36} -> 0 | J13: {=((Config!$F36*Commandes!J13)+IF(ROUND((J$8-Config!$C$7)/31,0)>=(Config!$D36+Config!$E36),INDEX(Commandes!$C13:Commandes!$BJ13,,COLUMN(J$8)-COLUMN($C$8)+1-(Config!$D36+Config!$E36)),0)*(1-Config!$F36))*Config!$C36} -> 0 | ... BJ13: {=((Config!$F36*Commandes!BJ13)+IF(ROUND((BJ$8-Config!$C$7)/31,0)>=(Config!$D36+Config!$E36),INDEX(Commandes!$C13:Commandes!$BJ13,,COLUMN(BJ$8)-COLUMN($C$8)+1-(Config!$D36+Config!$E36)),0)*(1-Config!$F36))*Config!$C36} -> 0
B14: =Config!$B$19 -> Commission ventes 2% | C14: {=((Config!$F37*Commandes!C14)+IF(ROUND((C$8-Config!$C$7)/31,0)>=(Config!$D37+Config!$E37),INDEX(Commandes!$C14:Commandes!$BJ14,,COLUMN(C$8)-COLUMN($C$8)+1-(Config!$D37+Config!$E37)),0)*(1-Config!$F37))*Config!$C37} -> 0 | D14: {=((Config!$F37*Commandes!D14)+IF(ROUND((D$8-Config!$C$7)/31,0)>=(Config!$D37+Config!$E37),INDEX(Commandes!$C14:Commandes!$BJ14,,COLUMN(D$8)-COLUMN($C$8)+1-(Config!$D37+Config!$E37)),0)*(1-Config!$F37))*Config!$C37} -> 0 | E14: {=((Config!$F37*Commandes!E14)+IF(ROUND((E$8-Config!$C$7)/31,0)>=(Config!$D37+Config!$E37),INDEX(Commandes!$C14:Commandes!$BJ14,,COLUMN(E$8)-COLUMN($C$8)+1-(Config!$D37+Config!$E37)),0)*(1-Config!$F37))*Config!$C37} -> 0 | F14: {=((Config!$F37*Commandes!F14)+IF(ROUND((F$8-Config!$C$7)/31,0)>=(Config!$D37+Config!$E37),INDEX(Commandes!$C14:Commandes!$BJ14,,COLUMN(F$8)-COLUMN($C$8)+1-(Config!$D37+Config!$E37)),0)*(1-Config!$F37))*Config!$C37} -> 0 | G14: {=((Config!$F37*Commandes!G14)+IF(ROUND((G$8-Config!$C$7)/31,0)>=(Config!$D37+Config!$E37),INDEX(Commandes!$C14:Commandes!$BJ14,,COLUMN(G$8)-COLUMN($C$8)+1-(Config!$D37+Config!$E37)),0)*(1-Config!$F37))*Config!$C37} -> 0 | H14: {=((Config!$F37*Commandes!H14)+IF(ROUND((H$8-Config!$C$7)/31,0)>=(Config!$D37+Config!$E37),INDEX(Commandes!$C14:Commandes!$BJ14,,COLUMN(H$8)-COLUMN($C$8)+1-(Config!$D37+Config!$E37)),0)*(1-Config!$F37))*Config!$C37} -> 0 | I14: {=((Config!$F37*Commandes!I14)+IF(ROUND((I$8-Config!$C$7)/31,0)>=(Config!$D37+Config!$E37),INDEX(Commandes!$C14:Commandes!$BJ14,,COLUMN(I$8)-COLUMN($C$8)+1-(Config!$D37+Config!$E37)),0)*(1-Config!$F37))*Config!$C37} -> 0 | J14: {=((Config!$F37*Commandes!J14)+IF(ROUND((J$8-Config!$C$7)/31,0)>=(Config!$D37+Config!$E37),INDEX(Commandes!$C14:Commandes!$BJ14,,COLUMN(J$8)-COLUMN($C$8)+1-(Config!$D37+Config!$E37)),0)*(1-Config!$F37))*Config!$C37} -> 0 | ... BJ14: {=((Config!$F37*Commandes!BJ14)+IF(ROUND((BJ$8-Config!$C$7)/31,0)>=(Config!$D37+Config!$E37),INDEX(Commandes!$C14:Commandes!$BJ14,,COLUMN(BJ$8)-COLUMN($C$8)+1-(Config!$D37+Config!$E37)),0)*(1-Config!$F37))*Config!$C37} -> 0
B15: =Config!$B$20 | C15: {=((Config!$F38*Commandes!C15)+IF(ROUND((C$8-Config!$C$7)/31,0)>=(Config!$D38+Config!$E38),INDEX(Commandes!$C15:Commandes!$BJ15,,COLUMN(C$8)-COLUMN($C$8)+1-(Config!$D38+Config!$E38)),0)*(1-Config!$F38))*Config!$C38} -> 0 | D15: {=((Config!$F38*Commandes!D15)+IF(ROUND((D$8-Config!$C$7)/31,0)>=(Config!$D38+Config!$E38),INDEX(Commandes!$C15:Commandes!$BJ15,,COLUMN(D$8)-COLUMN($C$8)+1-(Config!$D38+Config!$E38)),0)*(1-Config!$F38))*Config!$C38} -> 0 | E15: {=((Config!$F38*Commandes!E15)+IF(ROUND((E$8-Config!$C$7)/31,0)>=(Config!$D38+Config!$E38),INDEX(Commandes!$C15:Commandes!$BJ15,,COLUMN(E$8)-COLUMN($C$8)+1-(Config!$D38+Config!$E38)),0)*(1-Config!$F38))*Config!$C38} -> 0 | F15: {=((Config!$F38*Commandes!F15)+IF(ROUND((F$8-Config!$C$7)/31,0)>=(Config!$D38+Config!$E38),INDEX(Commandes!$C15:Commandes!$BJ15,,COLUMN(F$8)-COLUMN($C$8)+1-(Config!$D38+Config!$E38)),0)*(1-Config!$F38))*Config!$C38} -> 0 | G15: {=((Config!$F38*Commandes!G15)+IF(ROUND((G$8-Config!$C$7)/31,0)>=(Config!$D38+Config!$E38),INDEX(Commandes!$C15:Commandes!$BJ15,,COLUMN(G$8)-COLUMN($C$8)+1-(Config!$D38+Config!$E38)),0)*(1-Config!$F38))*Config!$C38} -> 0 | H15: {=((Config!$F38*Commandes!H15)+IF(ROUND((H$8-Config!$C$7)/31,0)>=(Config!$D38+Config!$E38),INDEX(Commandes!$C15:Commandes!$BJ15,,COLUMN(H$8)-COLUMN($C$8)+1-(Config!$D38+Config!$E38)),0)*(1-Config!$F38))*Config!$C38} -> 0 | I15: {=((Config!$F38*Commandes!I15)+IF(ROUND((I$8-Config!$C$7)/31,0)>=(Config!$D38+Config!$E38),INDEX(Commandes!$C15:Commandes!$BJ15,,COLUMN(I$8)-COLUMN($C$8)+1-(Config!$D38+Config!$E38)),0)*(1-Config!$F38))*Config!$C38} -> 0 | J15: {=((Config!$F38*Commandes!J15)+IF(ROUND((J$8-Config!$C$7)/31,0)>=(Config!$D38+Config!$E38),INDEX(Commandes!$C15:Commandes!$BJ15,,COLUMN(J$8)-COLUMN($C$8)+1-(Config!$D38+Config!$E38)),0)*(1-Config!$F38))*Config!$C38} -> 0 | ... BJ15: {=((Config!$F38*Commandes!BJ15)+IF(ROUND((BJ$8-Config!$C$7)/31,0)>=(Config!$D38+Config!$E38),INDEX(Commandes!$C15:Commandes!$BJ15,,COLUMN(BJ$8)-COLUMN($C$8)+1-(Config!$D38+Config!$E38)),0)*(1-Config!$F38))*Config!$C38} -> 0
B16: =Config!$B$21 | C16: {=((Config!$F39*Commandes!C16)+IF(ROUND((C$8-Config!$C$7)/31,0)>=(Config!$D39+Config!$E39),INDEX(Commandes!$C16:Commandes!$BJ16,,COLUMN(C$8)-COLUMN($C$8)+1-(Config!$D39+Config!$E39)),0)*(1-Config!$F39))*Config!$C39} -> 0 | D16: {=((Config!$F39*Commandes!D16)+IF(ROUND((D$8-Config!$C$7)/31,0)>=(Config!$D39+Config!$E39),INDEX(Commandes!$C16:Commandes!$BJ16,,COLUMN(D$8)-COLUMN($C$8)+1-(Config!$D39+Config!$E39)),0)*(1-Config!$F39))*Config!$C39} -> 0 | E16: {=((Config!$F39*Commandes!E16)+IF(ROUND((E$8-Config!$C$7)/31,0)>=(Config!$D39+Config!$E39),INDEX(Commandes!$C16:Commandes!$BJ16,,COLUMN(E$8)-COLUMN($C$8)+1-(Config!$D39+Config!$E39)),0)*(1-Config!$F39))*Config!$C39} -> 0 | F16: {=((Config!$F39*Commandes!F16)+IF(ROUND((F$8-Config!$C$7)/31,0)>=(Config!$D39+Config!$E39),INDEX(Commandes!$C16:Commandes!$BJ16,,COLUMN(F$8)-COLUMN($C$8)+1-(Config!$D39+Config!$E39)),0)*(1-Config!$F39))*Config!$C39} -> 0 | G16: {=((Config!$F39*Commandes!G16)+IF(ROUND((G$8-Config!$C$7)/31,0)>=(Config!$D39+Config!$E39),INDEX(Commandes!$C16:Commandes!$BJ16,,COLUMN(G$8)-COLUMN($C$8)+1-(Config!$D39+Config!$E39)),0)*(1-Config!$F39))*Config!$C39} -> 0 | H16: {=((Config!$F39*Commandes!H16)+IF(ROUND((H$8-Config!$C$7)/31,0)>=(Config!$D39+Config!$E39),INDEX(Commandes!$C16:Commandes!$BJ16,,COLUMN(H$8)-COLUMN($C$8)+1-(Config!$D39+Config!$E39)),0)*(1-Config!$F39))*Config!$C39} -> 0 | I16: {=((Config!$F39*Commandes!I16)+IF(ROUND((I$8-Config!$C$7)/31,0)>=(Config!$D39+Config!$E39),INDEX(Commandes!$C16:Commandes!$BJ16,,COLUMN(I$8)-COLUMN($C$8)+1-(Config!$D39+Config!$E39)),0)*(1-Config!$F39))*Config!$C39} -> 0 | J16: {=((Config!$F39*Commandes!J16)+IF(ROUND((J$8-Config!$C$7)/31,0)>=(Config!$D39+Config!$E39),INDEX(Commandes!$C16:Commandes!$BJ16,,COLUMN(J$8)-COLUMN($C$8)+1-(Config!$D39+Config!$E39)),0)*(1-Config!$F39))*Config!$C39} -> 0 | ... BJ16: {=((Config!$F39*Commandes!BJ16)+IF(ROUND((BJ$8-Config!$C$7)/31,0)>=(Config!$D39+Config!$E39),INDEX(Commandes!$C16:Commandes!$BJ16,,COLUMN(BJ$8)-COLUMN($C$8)+1-(Config!$D39+Config!$E39)),0)*(1-Config!$F39))*Config!$C39} -> 0
B17: =Config!$B$22 | C17: {=((Config!$F40*Commandes!C17)+IF(ROUND((C$8-Config!$C$7)/31,0)>=(Config!$D40+Config!$E40),INDEX(Commandes!$C17:Commandes!$BJ17,,COLUMN(C$8)-COLUMN($C$8)+1-(Config!$D40+Config!$E40)),0)*(1-Config!$F40))*Config!$C40} -> 0 | D17: {=((Config!$F40*Commandes!D17)+IF(ROUND((D$8-Config!$C$7)/31,0)>=(Config!$D40+Config!$E40),INDEX(Commandes!$C17:Commandes!$BJ17,,COLUMN(D$8)-COLUMN($C$8)+1-(Config!$D40+Config!$E40)),0)*(1-Config!$F40))*Config!$C40} -> 0 | E17: {=((Config!$F40*Commandes!E17)+IF(ROUND((E$8-Config!$C$7)/31,0)>=(Config!$D40+Config!$E40),INDEX(Commandes!$C17:Commandes!$BJ17,,COLUMN(E$8)-COLUMN($C$8)+1-(Config!$D40+Config!$E40)),0)*(1-Config!$F40))*Config!$C40} -> 0 | F17: {=((Config!$F40*Commandes!F17)+IF(ROUND((F$8-Config!$C$7)/31,0)>=(Config!$D40+Config!$E40),INDEX(Commandes!$C17:Commandes!$BJ17,,COLUMN(F$8)-COLUMN($C$8)+1-(Config!$D40+Config!$E40)),0)*(1-Config!$F40))*Config!$C40} -> 0 | G17: {=((Config!$F40*Commandes!G17)+IF(ROUND((G$8-Config!$C$7)/31,0)>=(Config!$D40+Config!$E40),INDEX(Commandes!$C17:Commandes!$BJ17,,COLUMN(G$8)-COLUMN($C$8)+1-(Config!$D40+Config!$E40)),0)*(1-Config!$F40))*Config!$C40} -> 0 | H17: {=((Config!$F40*Commandes!H17)+IF(ROUND((H$8-Config!$C$7)/31,0)>=(Config!$D40+Config!$E40),INDEX(Commandes!$C17:Commandes!$BJ17,,COLUMN(H$8)-COLUMN($C$8)+1-(Config!$D40+Config!$E40)),0)*(1-Config!$F40))*Config!$C40} -> 0 | I17: {=((Config!$F40*Commandes!I17)+IF(ROUND((I$8-Config!$C$7)/31,0)>=(Config!$D40+Config!$E40),INDEX(Commandes!$C17:Commandes!$BJ17,,COLUMN(I$8)-COLUMN($C$8)+1-(Config!$D40+Config!$E40)),0)*(1-Config!$F40))*Config!$C40} -> 0 | J17: {=((Config!$F40*Commandes!J17)+IF(ROUND((J$8-Config!$C$7)/31,0)>=(Config!$D40+Config!$E40),INDEX(Commandes!$C17:Commandes!$BJ17,,COLUMN(J$8)-COLUMN($C$8)+1-(Config!$D40+Config!$E40)),0)*(1-Config!$F40))*Config!$C40} -> 0 | ... BJ17: {=((Config!$F40*Commandes!BJ17)+IF(ROUND((BJ$8-Config!$C$7)/31,0)>=(Config!$D40+Config!$E40),INDEX(Commandes!$C17:Commandes!$BJ17,,COLUMN(BJ$8)-COLUMN($C$8)+1-(Config!$D40+Config!$E40)),0)*(1-Config!$F40))*Config!$C40} -> 0
B18: =Config!$B$23 | C18: {=((Config!$F41*Commandes!C18)+IF(ROUND((C$8-Config!$C$7)/31,0)>=(Config!$D41+Config!$E41),INDEX(Commandes!$C18:Commandes!$BJ18,,COLUMN(C$8)-COLUMN($C$8)+1-(Config!$D41+Config!$E41)),0)*(1-Config!$F41))*Config!$C41} -> 0 | D18: {=((Config!$F41*Commandes!D18)+IF(ROUND((D$8-Config!$C$7)/31,0)>=(Config!$D41+Config!$E41),INDEX(Commandes!$C18:Commandes!$BJ18,,COLUMN(D$8)-COLUMN($C$8)+1-(Config!$D41+Config!$E41)),0)*(1-Config!$F41))*Config!$C41} -> 0 | E18: {=((Config!$F41*Commandes!E18)+IF(ROUND((E$8-Config!$C$7)/31,0)>=(Config!$D41+Config!$E41),INDEX(Commandes!$C18:Commandes!$BJ18,,COLUMN(E$8)-COLUMN($C$8)+1-(Config!$D41+Config!$E41)),0)*(1-Config!$F41))*Config!$C41} -> 0 | F18: {=((Config!$F41*Commandes!F18)+IF(ROUND((F$8-Config!$C$7)/31,0)>=(Config!$D41+Config!$E41),INDEX(Commandes!$C18:Commandes!$BJ18,,COLUMN(F$8)-COLUMN($C$8)+1-(Config!$D41+Config!$E41)),0)*(1-Config!$F41))*Config!$C41} -> 0 | G18: {=((Config!$F41*Commandes!G18)+IF(ROUND((G$8-Config!$C$7)/31,0)>=(Config!$D41+Config!$E41),INDEX(Commandes!$C18:Commandes!$BJ18,,COLUMN(G$8)-COLUMN($C$8)+1-(Config!$D41+Config!$E41)),0)*(1-Config!$F41))*Config!$C41} -> 0 | H18: {=((Config!$F41*Commandes!H18)+IF(ROUND((H$8-Config!$C$7)/31,0)>=(Config!$D41+Config!$E41),INDEX(Commandes!$C18:Commandes!$BJ18,,COLUMN(H$8)-COLUMN($C$8)+1-(Config!$D41+Config!$E41)),0)*(1-Config!$F41))*Config!$C41} -> 0 | I18: {=((Config!$F41*Commandes!I18)+IF(ROUND((I$8-Config!$C$7)/31,0)>=(Config!$D41+Config!$E41),INDEX(Commandes!$C18:Commandes!$BJ18,,COLUMN(I$8)-COLUMN($C$8)+1-(Config!$D41+Config!$E41)),0)*(1-Config!$F41))*Config!$C41} -> 0 | J18: {=((Config!$F41*Commandes!J18)+IF(ROUND((J$8-Config!$C$7)/31,0)>=(Config!$D41+Config!$E41),INDEX(Commandes!$C18:Commandes!$BJ18,,COLUMN(J$8)-COLUMN($C$8)+1-(Config!$D41+Config!$E41)),0)*(1-Config!$F41))*Config!$C41} -> 0 | ... BJ18: {=((Config!$F41*Commandes!BJ18)+IF(ROUND((BJ$8-Config!$C$7)/31,0)>=(Config!$D41+Config!$E41),INDEX(Commandes!$C18:Commandes!$BJ18,,COLUMN(BJ$8)-COLUMN($C$8)+1-(Config!$D41+Config!$E41)),0)*(1-Config!$F41))*Config!$C41} -> 0
B19: =Config!$B$24 | C19: {=((Config!$F42*Commandes!C19)+IF(ROUND((C$8-Config!$C$7)/31,0)>=(Config!$D42+Config!$E42),INDEX(Commandes!$C19:Commandes!$BJ19,,COLUMN(C$8)-COLUMN($C$8)+1-(Config!$D42+Config!$E42)),0)*(1-Config!$F42))*Config!$C42} -> 0 | D19: {=((Config!$F42*Commandes!D19)+IF(ROUND((D$8-Config!$C$7)/31,0)>=(Config!$D42+Config!$E42),INDEX(Commandes!$C19:Commandes!$BJ19,,COLUMN(D$8)-COLUMN($C$8)+1-(Config!$D42+Config!$E42)),0)*(1-Config!$F42))*Config!$C42} -> 0 | E19: {=((Config!$F42*Commandes!E19)+IF(ROUND((E$8-Config!$C$7)/31,0)>=(Config!$D42+Config!$E42),INDEX(Commandes!$C19:Commandes!$BJ19,,COLUMN(E$8)-COLUMN($C$8)+1-(Config!$D42+Config!$E42)),0)*(1-Config!$F42))*Config!$C42} -> 0 | F19: {=((Config!$F42*Commandes!F19)+IF(ROUND((F$8-Config!$C$7)/31,0)>=(Config!$D42+Config!$E42),INDEX(Commandes!$C19:Commandes!$BJ19,,COLUMN(F$8)-COLUMN($C$8)+1-(Config!$D42+Config!$E42)),0)*(1-Config!$F42))*Config!$C42} -> 0 | G19: {=((Config!$F42*Commandes!G19)+IF(ROUND((G$8-Config!$C$7)/31,0)>=(Config!$D42+Config!$E42),INDEX(Commandes!$C19:Commandes!$BJ19,,COLUMN(G$8)-COLUMN($C$8)+1-(Config!$D42+Config!$E42)),0)*(1-Config!$F42))*Config!$C42} -> 0 | H19: {=((Config!$F42*Commandes!H19)+IF(ROUND((H$8-Config!$C$7)/31,0)>=(Config!$D42+Config!$E42),INDEX(Commandes!$C19:Commandes!$BJ19,,COLUMN(H$8)-COLUMN($C$8)+1-(Config!$D42+Config!$E42)),0)*(1-Config!$F42))*Config!$C42} -> 0 | I19: {=((Config!$F42*Commandes!I19)+IF(ROUND((I$8-Config!$C$7)/31,0)>=(Config!$D42+Config!$E42),INDEX(Commandes!$C19:Commandes!$BJ19,,COLUMN(I$8)-COLUMN($C$8)+1-(Config!$D42+Config!$E42)),0)*(1-Config!$F42))*Config!$C42} -> 0 | J19: {=((Config!$F42*Commandes!J19)+IF(ROUND((J$8-Config!$C$7)/31,0)>=(Config!$D42+Config!$E42),INDEX(Commandes!$C19:Commandes!$BJ19,,COLUMN(J$8)-COLUMN($C$8)+1-(Config!$D42+Config!$E42)),0)*(1-Config!$F42))*Config!$C42} -> 0 | ... BJ19: {=((Config!$F42*Commandes!BJ19)+IF(ROUND((BJ$8-Config!$C$7)/31,0)>=(Config!$D42+Config!$E42),INDEX(Commandes!$C19:Commandes!$BJ19,,COLUMN(BJ$8)-COLUMN($C$8)+1-(Config!$D42+Config!$E42)),0)*(1-Config!$F42))*Config!$C42} -> 0
B20: =Config!$B$25 | C20: {=((Config!$F43*Commandes!C20)+IF(ROUND((C$8-Config!$C$7)/31,0)>=(Config!$D43+Config!$E43),INDEX(Commandes!$C20:Commandes!$BJ20,,COLUMN(C$8)-COLUMN($C$8)+1-(Config!$D43+Config!$E43)),0)*(1-Config!$F43))*Config!$C43} -> 0 | D20: {=((Config!$F43*Commandes!D20)+IF(ROUND((D$8-Config!$C$7)/31,0)>=(Config!$D43+Config!$E43),INDEX(Commandes!$C20:Commandes!$BJ20,,COLUMN(D$8)-COLUMN($C$8)+1-(Config!$D43+Config!$E43)),0)*(1-Config!$F43))*Config!$C43} -> 0 | E20: {=((Config!$F43*Commandes!E20)+IF(ROUND((E$8-Config!$C$7)/31,0)>=(Config!$D43+Config!$E43),INDEX(Commandes!$C20:Commandes!$BJ20,,COLUMN(E$8)-COLUMN($C$8)+1-(Config!$D43+Config!$E43)),0)*(1-Config!$F43))*Config!$C43} -> 0 | F20: {=((Config!$F43*Commandes!F20)+IF(ROUND((F$8-Config!$C$7)/31,0)>=(Config!$D43+Config!$E43),INDEX(Commandes!$C20:Commandes!$BJ20,,COLUMN(F$8)-COLUMN($C$8)+1-(Config!$D43+Config!$E43)),0)*(1-Config!$F43))*Config!$C43} -> 0 | G20: {=((Config!$F43*Commandes!G20)+IF(ROUND((G$8-Config!$C$7)/31,0)>=(Config!$D43+Config!$E43),INDEX(Commandes!$C20:Commandes!$BJ20,,COLUMN(G$8)-COLUMN($C$8)+1-(Config!$D43+Config!$E43)),0)*(1-Config!$F43))*Config!$C43} -> 0 | H20: {=((Config!$F43*Commandes!H20)+IF(ROUND((H$8-Config!$C$7)/31,0)>=(Config!$D43+Config!$E43),INDEX(Commandes!$C20:Commandes!$BJ20,,COLUMN(H$8)-COLUMN($C$8)+1-(Config!$D43+Config!$E43)),0)*(1-Config!$F43))*Config!$C43} -> 0 | I20: {=((Config!$F43*Commandes!I20)+IF(ROUND((I$8-Config!$C$7)/31,0)>=(Config!$D43+Config!$E43),INDEX(Commandes!$C20:Commandes!$BJ20,,COLUMN(I$8)-COLUMN($C$8)+1-(Config!$D43+Config!$E43)),0)*(1-Config!$F43))*Config!$C43} -> 0 | J20: {=((Config!$F43*Commandes!J20)+IF(ROUND((J$8-Config!$C$7)/31,0)>=(Config!$D43+Config!$E43),INDEX(Commandes!$C20:Commandes!$BJ20,,COLUMN(J$8)-COLUMN($C$8)+1-(Config!$D43+Config!$E43)),0)*(1-Config!$F43))*Config!$C43} -> 0 | ... BJ20: {=((Config!$F43*Commandes!BJ20)+IF(ROUND((BJ$8-Config!$C$7)/31,0)>=(Config!$D43+Config!$E43),INDEX(Commandes!$C20:Commandes!$BJ20,,COLUMN(BJ$8)-COLUMN($C$8)+1-(Config!$D43+Config!$E43)),0)*(1-Config!$F43))*Config!$C43} -> 0
B22: TOTAL | C22: =SUM(C9:C20) -> 0 | D22: =SUM(D9:D20) -> 0 | E22: =SUM(E9:E20) -> 1700000 | F22: =SUM(F9:F20) -> 3250000 | G22: =SUM(G9:G20) -> 6125000 | H22: =SUM(H9:H20) -> 21200000 | I22: =SUM(I9:I20) -> 28850000 | J22: =SUM(J9:J20) -> 34015000 | ... BJ22: =SUM(BJ9:BJ20) -> 968000000
B23: TOTAL annuel cumulé | C23: =C22 -> 0 | D23: =C23+D22 -> 0 | E23: =D23+E22 -> 1700000 | F23: =E23+F22 -> 4950000 | G23: =F23+G22 -> 11075000 | H23: =G23+H22 -> 32275000 | I23: =H23+I22 -> 61125000 | J23: =I23+J22 -> 95140000 | K23: =J23+K22 -> 134336500 | ... N23: =M23+N22 -> 2.6820576e+08 | O23: =O22 -> 63723076 | P23: =O23+P22 -> 1.3317692e+08 | Q23: =P23+Q22 -> 2.1104423e+08 | R23: =Q23+R22 -> 292553358 | S23: =R23+S22 -> 3.7798977e+08 | T23: =S23+T22 -> 4.7021029e+08 | U23: =T23+U22 -> 5.6716094e+08 | V23: =U23+V22 -> 6.7189925e+08 | W23: =V23+W22 -> 7.8512214e+08 | ... Z23: =Y23+Z22 -> 1171803094 | AA23: =AA22 -> 1.5803635e+08 | AB23: =AA23+AB22 -> 3.2920679e+08 | AC23: =AB23+AC22 -> 5.1366983e+08 | AD23: =AC23+AD22 -> 7.1474864e+08 | AE23: =AD23+AE22 -> 936597146 | AF23: =AE23+AF22 -> 1184407782 | AG23: =AF23+AG22 -> 1464671076 | AH23: =AG23+AH22 -> 1785500194 | AI23: =AH23+AI22 -> 2157036592 | ... AL23: =AK23+AL22 -> 3374107710 | AM23: =AM22 -> 373000000 | AN23: =AM23+AN22 -> 746000000 | AO23: =AN23+AO22 -> 1119000000 | AP23: =AO23+AP22 -> 1537000000 | AQ23: =AP23+AQ22 -> 1955000000 | AR23: =AQ23+AR22 -> 2373000000 | AS23: =AR23+AS22 -> 2896000000 | AT23: =AS23+AT22 -> 3419000000 | AU23: =AT23+AU22 -> 3942000000 | ... AX23: =AW23+AX22 -> 5646000000 | AY23: =AY22 -> 768000000 | AZ23: =AY23+AZ22 -> 1536000000 | BA23: =AZ23+BA22 -> 2304000000 | BB23: =BA23+BB22 -> 3072000000 | BC23: =BB23+BC22 -> 3840000000 | BD23: =BC23+BD22 -> 4608000000 | BE23: =BD23+BE22 -> 5576000000 | BF23: =BE23+BF22 -> 6544000000 | BG23: =BF23+BG22 -> 7512000000 | ... BJ23: =BI23+BJ22 -> 10416000000
C25: Année 1 | O25: Année 2 | AA25: Année 3 | AN25: Année 4 | AY25: Année 5
B26: Charges totales | C26: =Config!$C$7 -> 45505 | D26: =DATE(YEAR(C26),MONTH(C26)+1,DAY(C26)) -> 45536 | E26: =DATE(YEAR(D26),MONTH(D26)+1,DAY(D26)) -> 45566 | F26: =DATE(YEAR(E26),MONTH(E26)+1,DAY(E26)) -> 45597 | G26: =DATE(YEAR(F26),MONTH(F26)+1,DAY(F26)) -> 45627 | H26: =DATE(YEAR(G26),MONTH(G26)+1,DAY(G26)) -> 45658 | I26: =DATE(YEAR(H26),MONTH(H26)+1,DAY(H26)) -> 45689 | J26: =DATE(YEAR(I26),MONTH(I26)+1,DAY(I26)) -> 45717 | K26: =DATE(YEAR(J26),MONTH(J26)+1,DAY(J26)) -> 45748 | ... BJ26: =DATE(YEAR(BI26),MONTH(BI26)+1,DAY(BI26)) -> 47300
B27: =Config!$B$14 -> Abonnement Basique | C27: =Config!$C32*Commandes!C9 -> 0 | D27: =Config!$C32*Commandes!D9 -> 0 | E27: =Config!$C32*Commandes!E9 -> 450000 | F27: =Config!$C32*Commandes!F9 -> 750000 | G27: =Config!$C32*Commandes!G9 -> 1125000 | H27: =Config!$C32*Commandes!H9 -> 1500000 | I27: =Config!$C32*Commandes!I9 -> 1650000 | J27: =Config!$C32*Commandes!J9 -> 1815000 | ... BJ27: =Config!$C32*Commandes!BJ9 -> 450000000
B28: =Config!$B$15 -> Abonnement Premium | C28: =Config!$C33*Commandes!C10 -> 0 | D28: =Config!$C33*Commandes!D10 -> 0 | E28: =Config!$C33*Commandes!E10 -> 1250000 | F28: =Config!$C33*Commandes!F10 -> 2500000 | G28: =Config!$C33*Commandes!G10 -> 5000000 | H28: =Config!$C33*Commandes!H10 -> 12500000 | I28: =Config!$C33*Commandes!I10 -> 20000000 | J28: =Config!$C33*Commandes!J10 -> 25000000 | ... BJ28: =Config!$C33*Commandes!BJ10 -> 500000000
B29: =Config!$B$16 -> Conseil Personnalisé | C29: =Config!$C34*Commandes!C11 -> 0 | D29: =Config!$C34*Commandes!D11 -> 0 | E29: =Config!$C34*Commandes!E11 -> 0 | F29: =Config!$C34*Commandes!F11 -> 0 | G29: =Config!$C34*Commandes!G11 -> 0 | H29: =Config!$C34*Commandes!H11 -> 7200000 | I29: =Config!$C34*Commandes!I11 -> 7200000 | J29: =Config!$C34*Commandes!J11 -> 7200000 | ... BJ29: =Config!$C34*Commandes!BJ11 -> 18000000
B30: =Config!$B$17 -> Plateforme de Marché en Ligne | C30: =Config!$C35*Commandes!C12 -> 0 | D30: =Config!$C35*Commandes!D12 -> 0 | E30: =Config!$C35*Commandes!E12 -> 0 | F30: =Config!$C35*Commandes!F12 -> 0 | G30: =Config!$C35*Commandes!G12 -> 0 | H30: =Config!$C35*Commandes!H12 -> 0 | I30: =Config!$C35*Commandes!I12 -> 0 | J30: =Config!$C35*Commandes!J12 -> 0 | ... BJ30: =Config!$C35*Commandes!BJ12 -> 0
B31: =Config!$B$18 -> Formations et Ateliers | C31: =Config!$C36*Commandes!C13 -> 0 | D31: =Config!$C36*Commandes!D13 -> 0 | E31: =Config!$C36*Commandes!E13 -> 0 | F31: =Config!$C36*Commandes!F13 -> 0 | G31: =Config!$C36*Commandes!G13 -> 0 | H31: =Config!$C36*Commandes!H13 -> 0 | I31: =Config!$C36*Commandes!I13 -> 0 | J31: =Config!$C36*Commandes!J13 -> 0 | ... BJ31: =Config!$C36*Commandes!BJ13 -> 0
B32: =Config!$B$19 -> Commission ventes 2% | C32: =Config!$C37*Commandes!C14 -> 0 | D32: =Config!$C37*Commandes!D14 -> 0 | E32: =Config!$C37*Commandes!E14 -> 0 | F32: =Config!$C37*Commandes!F14 -> 0 | G32: =Config!$C37*Commandes!G14 -> 0 | H32: =Config!$C37*Commandes!H14 -> 0 | I32: =Config!$C37*Commandes!I14 -> 0 | J32: =Config!$C37*Commandes!J14 -> 0 | ... BJ32: =Config!$C37*Commandes!BJ14 -> 0
B33: =Config!$B$20 | C33: =Config!$C38*Commandes!C15 -> 0 | D33: =Config!$C38*Commandes!D15 -> 0 | E33: =Config!$C38*Commandes!E15 -> 0 | F33: =Config!$C38*Commandes!F15 -> 0 | G33: =Config!$C38*Commandes!G15 -> 0 | H33: =Config!$C38*Commandes!H15 -> 0 | I33: =Config!$C38*Commandes!I15 -> 0 | J33: =Config!$C38*Commandes!J15 -> 0 | ... BJ33: =Config!$C38*Commandes!BJ15 -> 0
B34: =Config!$B$21 | C34: =Config!$C39*Commandes!C16 -> 0 | D34: =Config!$C39*Commandes!D16 -> 0 | E34: =Config!$C39*Commandes!E16 -> 0 | F34: =Config!$C39*Commandes!F16 -> 0 | G34: =Config!$C39*Commandes!G16 -> 0 | H34: =Config!$C39*Commandes!H16 -> 0 | I34: =Config!$C39*Commandes!I16 -> 0 | J34: =Config!$C39*Commandes!J16 -> 0 | ... BJ34: =Config!$C39*Commandes!BJ16 -> 0
B35: =Config!$B$22 | C35: =Config!$C40*Commandes!C17 -> 0 | D35: =Config!$C40*Commandes!D17 -> 0 | E35: =Config!$C40*Commandes!E17 -> 0 | F35: =Config!$C40*Commandes!F17 -> 0 | G35: =Config!$C40*Commandes!G17 -> 0 | H35: =Config!$C40*Commandes!H17 -> 0 | I35: =Config!$C40*Commandes!I17 -> 0 | J35: =Config!$C40*Commandes!J17 -> 0 | ... BJ35: =Config!$C40*Commandes!BJ17 -> 0
B36: =Config!$B$23 | C36: =Config!$C41*Commandes!C18 -> 0 | D36: =Config!$C41*Commandes!D18 -> 0 | E36: =Config!$C41*Commandes!E18 -> 0 | F36: =Config!$C41*Commandes!F18 -> 0 | G36: =Config!$C41*Commandes!G18 -> 0 | H36: =Config!$C41*Commandes!H18 -> 0 | I36: =Config!$C41*Commandes!I18 -> 0 | J36: =Config!$C41*Commandes!J18 -> 0 | ... BJ36: =Config!$C41*Commandes!BJ18 -> 0
B37: =Config!$B$24 | C37: =Config!$C42*Commandes!C19 -> 0 | D37: =Config!$C42*Commandes!D19 -> 0 | E37: =Config!$C42*Commandes!E19 -> 0 | F37: =Config!$C42*Commandes!F19 -> 0 | G37: =Config!$C42*Commandes!G19 -> 0 | H37: =Config!$C42*Commandes!H19 -> 0 | I37: =Config!$C42*Commandes!I19 -> 0 | J37: =Config!$C42*Commandes!J19 -> 0 | ... BJ37: =Config!$C42*Commandes!BJ19 -> 0
B38: =Config!$B$25 | C38: =Config!$C43*Commandes!C20 -> 0 | D38: =Config!$C43*Commandes!D20 -> 0 | E38: =Config!$C43*Commandes!E20 -> 0 | F38: =Config!$C43*Commandes!F20 -> 0 | G38: =Config!$C43*Commandes!G20 -> 0 | H38: =Config!$C43*Commandes!H20 -> 0 | I38: =Config!$C43*Commandes!I20 -> 0 | J38: =Config!$C43*Commandes!J20 -> 0 | ... BJ38: =Config!$C43*Commandes!BJ20 -> 0
B40: TOTAL | C40: =SUM(C27:C38) -> 0 | D40: =SUM(D27:D38) -> 0 | E40: =SUM(E27:E38) -> 1700000 | F40: =SUM(F27:F38) -> 3250000 | G40: =SUM(G27:G38) -> 6125000 | H40: =SUM(H27:H38) -> 21200000 | I40: =SUM(I27:I38) -> 28850000 | J40: =SUM(J27:J38) -> 34015000 | ... BJ40: =SUM(BJ27:BJ38) -> 968000000
B41: TOTAL annuel cumulé | C41: =C40 -> 0 | D41: =C41+D40 -> 0 | E41: =D41+E40 -> 1700000 | F41: =E41+F40 -> 4950000 | G41: =F41+G40 -> 11075000 | H41: =G41+H40 -> 32275000 | I41: =H41+I40 -> 61125000 | J41: =I41+J40 -> 95140000 | K41: =J41+K40 -> 134336500 | ... N41: =M41+N40 -> 2.6820576e+08 | O41: =O40 -> 63723076 | P41: =O41+P40 -> 1.3317692e+08 | Q41: =P41+Q40 -> 2.1104423e+08 | R41: =Q41+R40 -> 292553358 | S41: =R41+S40 -> 3.7798977e+08 | T41: =S41+T40 -> 4.7021029e+08 | U41: =T41+U40 -> 5.6716094e+08 | V41: =U41+V40 -> 6.7189925e+08 | W41: =V41+W40 -> 7.8512214e+08 | ... Z41: =Y41+Z40 -> 1171803094 | AA41: =AA40 -> 1.5803635e+08 | AB41: =AA41+AB40 -> 3.2920679e+08 | AC41: =AB41+AC40 -> 5.1366983e+08 | AD41: =AC41+AD40 -> 7.1474864e+08 | AE41: =AD41+AE40 -> 936597146 | AF41: =AE41+AF40 -> 1184407782 | AG41: =AF41+AG40 -> 1464671076 | AH41: =AG41+AH40 -> 1785500194 | AI41: =AH41+AI40 -> 2157036592 | ... AL41: =AK41+AL40 -> 3374107710 | AM41: =AM40 -> 373000000 | AN41: =AM41+AN40 -> 746000000 | AO41: =AN41+AO40 -> 1119000000 | AP41: =AO41+AP40 -> 1537000000 | AQ41: =AP41+AQ40 -> 1955000000 | AR41: =AQ41+AR40 -> 2373000000 | AS41: =AR41+AS40 -> 2896000000 | AT41: =AS41+AT40 -> 3419000000 | AU41: =AT41+AU40 -> 3942000000 | ... AX41: =AW41+AX40 -> 5646000000 | AY41: =AY40 -> 768000000 | AZ41: =AY41+AZ40 -> 1536000000 | BA41: =AZ41+BA40 -> 2304000000 | BB41: =BA41+BB40 -> 3072000000 | BC41: =BB41+BC40 -> 3840000000 | BD41: =BC41+BD40 -> 4608000000 | BE41: =BD41+BE40 -> 5576000000 | BF41: =BE41+BF40 -> 6544000000 | BG41: =BF41+BG40 -> 7512000000 | ... BJ41: =BI41+BJ40 -> 10416000000

Sheet Personnel - Calculs auto
B2: Calculs auto liés au Personnel
C5: Année 1 | D5: Année 2 | E5: Année 3 | F5: Année 4 | G5: Année 5
B6: Nb employés | C6: =Personnel!P30 -> 3.1666667 | D6: =Personnel!AD30 -> 4.5833333 | E6: =Personnel!AH30 -> 6.5 | F6: =Personnel!AL30 -> 0 | G6: =Personnel!AP30 -> 0
B8: Salaires bruts
B9: Année 1 | O9: Année 2 | AB9: Année 3 | AE9: Année 4 | AH9: Année 5
B10: =Config!$C$7 -> 45505 | C10: =DATE(YEAR(B10),MONTH(B10)+1,DAY(B10)) -> 45536 | D10: =DATE(YEAR(C10),MONTH(C10)+1,DAY(C10)) -> 45566 | E10: =DATE(YEAR(D10),MONTH(D10)+1,DAY(D10)) -> 45597 | F10: =DATE(YEAR(E10),MONTH(E10)+1,DAY(E10)) -> 45627 | G10: =DATE(YEAR(F10),MONTH(F10)+1,DAY(F10)) -> 45658 | H10: =DATE(YEAR(G10),MONTH(G10)+1,DAY(G10)) -> 45689 | I10: =DATE(YEAR(H10),MONTH(H10)+1,DAY(H10)) -> 45717 | J10: =DATE(YEAR(I10),MONTH(I10)+1,DAY(I10)) -> 45748 | ... M10: =DATE(YEAR(L10),MONTH(L10)+1,DAY(L10)) -> 45839 | N10: Total | O10: =DATE(YEAR(M10),MONTH(M10)+1,DAY(M10)) -> 45870 | P10: =DATE(YEAR(O10),MONTH(O10)+1,DAY(O10)) -> 45901 | Q10: =DATE(YEAR(P10),MONTH(P10)+1,DAY(P10)) -> 45931 | R10: =DATE(YEAR(Q10),MONTH(Q10)+1,DAY(Q10)) -> 45962 | S10: =DATE(YEAR(R10),MONTH(R10)+1,DAY(R10)) -> 45992 | T10: =DATE(YEAR(S10),MONTH(S10)+1,DAY(S10)) -> 46023 | U10: =DATE(YEAR(T10),MONTH(T10)+1,DAY(T10)) -> 46054 | V10: =DATE(YEAR(U10),MONTH(U10)+1,DAY(U10)) -> 46082 | W10: =DATE(YEAR(V10),MONTH(V10)+1,DAY(V10)) -> 46113 | ... Z10: =DATE(YEAR(Y10),MONTH(Y10)+1,DAY(Y10)) -> 46204 | AA10: Total | AB10: S1 | AC10: S2 | AD10: Total | AE10: S1 | AF10: S2 | AG10: Total | AH10: S1 | AI10: S2 | AJ10: Total
B11: =Personnel!$C10*Personnel!D10/12 -> 0 | C11: =Personnel!$C10*Personnel!E10/12 -> 0 | D11: =Personnel!$C10*Personnel!F10/12 -> 0 | E11: =Personnel!$C10*Personnel!G10/12 -> 0 | F11: =Personnel!$C10*Personnel!H10/12 -> 0 | G11: =Personnel!$C10*Personnel!I10/12 -> 0 | H11: =Personnel!$C10*Personnel!J10/12 -> 0 | I11: =Personnel!$C10*Personnel!K10/12 -> 0 | ... M11: =Personnel!$C10*Personnel!O10/12 -> 0 | N11: =SUM(B11:M11) -> 0 | O11: =Personnel!$Q10*Personnel!R10/12 -> 0 | P11: =Personnel!$Q10*Personnel!S10/12 -> 0 | Q11: =Personnel!$Q10*Personnel!T10/12 -> 0 | R11: =Personnel!$Q10*Personnel!U10/12 -> 0 | S11: =Personnel!$Q10*Personnel!V10/12 -> 0 | T11: =Personnel!$Q10*Personnel!W10/12 -> 0 | U11: =Personnel!$Q10*Personnel!X10/12 -> 0 | V11: =Personnel!$Q10*Personnel!Y10/12 -> 0 | ... Z11: =Personnel!$Q10*Personnel!AC10/12 -> 0 | AA11: =SUM(O11:Z11) -> 0 | AB11: =Personnel!$AE10*Personnel!AF10/2 -> 0 | AC11: =Personnel!$AE10*Personnel!AG10/2 -> 0 | AD11: =SUM(AB11:AC11) -> 0 | AE11: =Personnel!$AI10*Personnel!AJ10/2 -> 0 | AF11: =Personnel!$AI10*Personnel!AK10/2 -> 0 | AG11: =SUM(AE11:AF11) -> 0 | AH11: =Personnel!$AM10*Personnel!AN10/2 -> 0 | AI11: =Personnel!$AM10*Personnel!AO10/2 -> 0 | AJ11: =SUM(AH11:AI11) -> 0
B12: =Personnel!$C11*Personnel!D11/12 -> 0 | C12: =Personnel!$C11*Personnel!E11/12 -> 0 | D12: =Personnel!$C11*Personnel!F11/12 -> 0 | E12: =Personnel!$C11*Personnel!G11/12 -> 0 | F12: =Personnel!$C11*Personnel!H11/12 -> 0 | G12: =Personnel!$C11*Personnel!I11/12 -> 0 | H12: =Personnel!$C11*Personnel!J11/12 -> 0 | I12: =Personnel!$C11*Personnel!K11/12 -> 0 | ... M12: =Personnel!$C11*Personnel!O11/12 -> 0 | N12: =SUM(B12:M12) -> 0 | O12: =Personnel!$Q11*Personnel!R11/12 -> 0 | P12: =Personnel!$Q11*Personnel!S11/12 -> 0 | Q12: =Personnel!$Q11*Personnel!T11/12 -> 0 | R12: =Personnel!$Q11*Personnel!U11/12 -> 0 | S12: =Personnel!$Q11*Personnel!V11/12 -> 0 | T12: =Personnel!$Q11*Personnel!W11/12 -> 0 | U12: =Personnel!$Q11*Personnel!X11/12 -> 0 | V12: =Personnel!$Q11*Personnel!Y11/12 -> 0 | ... Z12: =Personnel!$Q11*Personnel!AC11/12 -> 0 | AA12: =SUM(O12:Z12) -> 0 | AB12: =Personnel!$AE11*Personnel!AF11/2 -> 0 | AC12: =Personnel!$AE11*Personnel!AG11/2 -> 0 | AD12: =SUM(AB12:AC12) -> 0 | AE12: =Personnel!$AI11*Personnel!AJ11/2 -> 0 | AF12: =Personnel!$AI11*Personnel!AK11/2 -> 0 | AG12: =SUM(AE12:AF12) -> 0 | AH12: =Personnel!$AM11*Personnel!AN11/2 -> 0 | AI12: =Personnel!$AM11*Personnel!AO11/2 -> 0 | AJ12: =SUM(AH12:AI12) -> 0
B13: =Personnel!$C12*Personnel!D12/12 -> 1300000 | C13: =Personnel!$C12*Personnel!E12/12 -> 1300000 | D13: =Personnel!$C12*Personnel!F12/12 -> 1300000 | E13: =Personnel!$C12*Personnel!G12/12 -> 1300000 | F13: =Personnel!$C12*Personnel!H12/12 -> 1300000 | G13: =Personnel!$C12*Personnel!I12/12 -> 1300000 | H13: =Personnel!$C12*Personnel!J12/12 -> 1300000 | I13: =Personnel!$C12*Personnel!K12/12 -> 1300000 | ... M13: =Personnel!$C12*Personnel!O12/12 -> 1300000 | N13: =SUM(B13:M13) -> 15600000 | O13: =Personnel!$Q12*Personnel!R12/12 -> 2616666.7 | P13: =Personnel!$Q12*Personnel!S12/12 -> 2616666.7 | Q13: =Personnel!$Q12*Personnel!T12/12 -> 2616666.7 | R13: =Personnel!$Q12*Personnel!U12/12 -> 2616666.7 | S13: =Personnel!$Q12*Personnel!V12/12 -> 2616666.7 | T13: =Personnel!$Q12*Personnel!W12/12 -> 2616666.7 | U13: =Personnel!$Q12*Personnel!X12/12 -> 2616666.7 | V13: =Personnel!$Q12*Personnel!Y12/12 -> 2616666.7 | ... Z13: =Personnel!$Q12*Personnel!AC12/12 -> 2616666.7 | AA13: =SUM(O13:Z13) -> 31400000 | AB13: =Personnel!$AE12*Personnel!AF12/2 -> 23850000 | AC13: =Personnel!$AE12*Personnel!AG12/2 -> 23850000 | AD13: =SUM(AB13:AC13) -> 47700000 | AE13: =Personnel!$AI12*Personnel!AJ12/2 -> 0 | AF13: =Personnel!$AI12*Personnel!AK12/2 -> 0 | AG13: =SUM(AE13:AF13) -> 0 | AH13: =Personnel!$AM12*Personnel!AN12/2 -> 0 | AI13: =Personnel!$AM12*Personnel!AO12/2 -> 0 | AJ13: =SUM(AH13:AI13) -> 0
B14: =Personnel!$C13*Personnel!D13/12 -> 1300000 | C14: =Personnel!$C13*Personnel!E13/12 -> 1300000 | D14: =Personnel!$C13*Personnel!F13/12 -> 1300000 | E14: =Personnel!$C13*Personnel!G13/12 -> 1300000 | F14: =Personnel!$C13*Personnel!H13/12 -> 1300000 | G14: =Personnel!$C13*Personnel!I13/12 -> 1300000 | H14: =Personnel!$C13*Personnel!J13/12 -> 1300000 | I14: =Personnel!$C13*Personnel!K13/12 -> 1300000 | ... M14: =Personnel!$C13*Personnel!O13/12 -> 1300000 | N14: =SUM(B14:M14) -> 15600000 | O14: =Personnel!$Q13*Personnel!R13/12 -> 2616666.7 | P14: =Personnel!$Q13*Personnel!S13/12 -> 2616666.7 | Q14: =Personnel!$Q13*Personnel!T13/12 -> 2616666.7 | R14: =Personnel!$Q13*Personnel!U13/12 -> 2616666.7 | S14: =Personnel!$Q13*Personnel!V13/12 -> 2616666.7 | T14: =Personnel!$Q13*Personnel!W13/12 -> 2616666.7 | U14: =Personnel!$Q13*Personnel!X13/12 -> 2616666.7 | V14: =Personnel!$Q13*Personnel!Y13/12 -> 2616666.7 | ... Z14: =Personnel!$Q13*Personnel!AC13/12 -> 2616666.7 | AA14: =SUM(O14:Z14) -> 31400000 | AB14: =Personnel!$AE13*Personnel!AF13/2 -> 23850000 | AC14: =Personnel!$AE13*Personnel!AG13/2 -> 23850000 | AD14: =SUM(AB14:AC14) -> 47700000 | AE14: =Personnel!$AI13*Personnel!AJ13/2 -> 0 | AF14: =Personnel!$AI13*Personnel!AK13/2 -> 0 | AG14: =SUM(AE14:AF14) -> 0 | AH14: =Personnel!$AM13*Personnel!AN13/2 -> 0 | AI14: =Personnel!$AM13*Personnel!AO13/2 -> 0 | AJ14: =SUM(AH14:AI14) -> 0
B15: =Personnel!$C14*Personnel!D14/12 -> 0 | C15: =Personnel!$C14*Personnel!E14/12 -> 0 | D15: =Personnel!$C14*Personnel!F14/12 -> 0 | E15: =Personnel!$C14*Personnel!G14/12 -> 0 | F15: =Personnel!$C14*Personnel!H14/12 -> 0 | G15: =Personnel!$C14*Personnel!I14/12 -> 650000 | H15: =Personnel!$C14*Personnel!J14/12 -> 650000 | I15: =Personnel!$C14*Personnel!K14/12 -> 650000 | ... M15: =Personnel!$C14*Personnel!O14/12 -> 650000 | N15: =SUM(B15:M15) -> 4550000 | O15: =Personnel!$Q14*Personnel!R14/12 -> 800000 | P15: =Personnel!$Q14*Personnel!S14/12 -> 800000 | Q15: =Personnel!$Q14*Personnel!T14/12 -> 800000 | R15: =Personnel!$Q14*Personnel!U14/12 -> 800000 | S15: =Personnel!$Q14*Personnel!V14/12 -> 800000 | T15: =Personnel!$Q14*Personnel!W14/12 -> 1600000 | U15: =Personnel!$Q14*Personnel!X14/12 -> 1600000 | V15: =Personnel!$Q14*Personnel!Y14/12 -> 1600000 | ... Z15: =Personnel!$Q14*Personnel!AC14/12 -> 1600000 | AA15: =SUM(O15:Z15) -> 15200000 | AB15: =Personnel!$AE14*Personnel!AF14/2 -> 15600000 | AC15: =Personnel!$AE14*Personnel!AG14/2 -> 23400000 | AD15: =SUM(AB15:AC15) -> 39000000 | AE15: =Personnel!$AI14*Personnel!AJ14/2 -> 0 | AF15: =Personnel!$AI14*Personnel!AK14/2 -> 0 | AG15: =SUM(AE15:AF15) -> 0 | AH15: =Personnel!$AM14*Personnel!AN14/2 -> 0 | AI15: =Personnel!$AM14*Personnel!AO14/2 -> 0 | AJ15: =SUM(AH15:AI15) -> 0
